Workbook
Name CategoryMap: CategoryMap!$A$2:$B$4

Sheet Read me
A1: Support worksheet — weighted kappa and consensus decision
A3: What this is.
A4: Shows, cell by cell, how the weighted kappa cited in the "Quality Assessment (Q4-Q8)" section of the article was calculated — to serve as auditable support for the consensus decision, not as a number to be taken on faith.
A6: Why weighted kappa, and not simple kappa.
A7: The Q1-Q8 answers sit on a 3-point ordinal scale: No (0) < Partial (0.5) < Yes (1). Cohen's simple kappa (1960) treats any disagreement as equally serious — "No vs. Yes" would weigh the same as "No vs. Partial", which ignores the scale's order. Cohen's weighted kappa (1968), with linear weights, penalizes disagreement in proportion to the distance between categories — the correct choice for an ordinal scale, and the same logic used for quality assessment in the software-engineering systematic-review literature.
A9: Why linear weighting, and not quadratic.
A10: Quadratic weighting penalizes a 2-step disagreement (No vs. Yes) 4x more than a 1-step disagreement — over-penalizing the extreme on a scale with only 3 points. Linear weighting penalizes proportionally (2x), a more conservative treatment and more common in systematic-review reports. See the "Weights" sheet.
A12: How to read the "Data" sheet.
A13: One row per (study, question) — 187 studies × 8 questions = 1,496 rows, the same total cited in the article. The response columns carry the models' real names (Opus, Sonnet) rather than "Rater 1/2": in the source CSV, Avaliador_1 is always an `opus` and Avaliador_2 always a `sonnet` in this corpus. The "Human consensus" column comes from the already-adjudicated consensus panel (`consenso_rsl.csv`) — shown here only to compare which rater each divergence followed, not to recompute the adjudication.
A15: How to read "Confusion_matrix" and "Kappa_by_question".
A16: Each question has a 3×3 contingency table (Opus in the rows, Sonnet in the columns), calculated with COUNTIFS over the "Data" sheet — change an answer in "Data" and the matrix and the kappa recalculate on their own. "Kappa_by_question" applies the weighted-kappa formula over each matrix and classifies the result using the Landis & Koch (1977) bands — the standard reference for "what counts as acceptable agreement" (used to justify the ≥ 0.60 threshold for gate G3).
A18: Cross-check.
... A25: MCHUGH, M. L. Interrater reliability: the kappa statistic. Biochemia Medica, v. 22, n. 3, p. 276-282, 2012.

Sheet Data
A1: Study_ID | B1: Question | C1: Response_Opus | D1: Response_Sonnet | E1: Code_Opus | F1: Code_Sonnet | G1: Step_difference | H1: Agrees | I1: Human_consensus | J1: Consensus_matches
A2: R003 | B2: Q1 | C2: Partial | D2: No | E2: =VLOOKUP(C2,CategoryMap,2,0) | F2: =VLOOKUP(D2,CategoryMap,2,0) | G2: =ABS(E2-F2) | H2: =IF(G2=0,"Yes","No") | I2: No | J2: =IF(I2="","",IF(AND(I2=C2,I2=D2),"Both",IF(I2=C2,"Opus",IF(I2=D2,"Sonnet","Neither"))))
A3: R003 | B3: Q2 | C3: Partial | D3: Partial | E3: =VLOOKUP(C3,CategoryMap,2,0) | F3: =VLOOKUP(D3,CategoryMap,2,0) | G3: =ABS(E3-F3) | H3: =IF(G3=0,"Yes","No") | I3: Partial | J3: =IF(I3="","",IF(AND(I3=C3,I3=D3),"Both",IF(I3=C3,"Opus",IF(I3=D3,"Sonnet","Neither"))))
A4: R003 | B4: Q3 | C4: Yes | D4: Partial | E4: =VLOOKUP(C4,CategoryMap,2,0) | F4: =VLOOKUP(D4,CategoryMap,2,0) | G4: =ABS(E4-F4) | H4: =IF(G4=0,"Yes","No") | I4: Partial | J4: =IF(I4="","",IF(AND(I4=C4,I4=D4),"Both",IF(I4=C4,"Opus",IF(I4=D4,"Sonnet","Neither"))))
A5: R003 | B5: Q4 | C5: Yes | D5: Yes | E5: =VLOOKUP(C5,CategoryMap,2,0) | F5: =VLOOKUP(D5,CategoryMap,2,0) | G5: =ABS(E5-F5) | H5: =IF(G5=0,"Yes","No") | I5: Yes | J5: =IF(I5="","",IF(AND(I5=C5,I5=D5),"Both",IF(I5=C5,"Opus",IF(I5=D5,"Sonnet","Neither"))))
A6: R003 | B6: Q5 | C6: Partial | D6: Yes | E6: =VLOOKUP(C6,CategoryMap,2,0) | F6: =VLOOKUP(D6,CategoryMap,2,0) | G6: =ABS(E6-F6) | H6: =IF(G6=0,"Yes","No") | I6: Partial | J6: =IF(I6="","",IF(AND(I6=C6,I6=D6),"Both",IF(I6=C6,"Opus",IF(I6=D6,"Sonnet","Neither"))))
A7: R003 | B7: Q6 | C7: Yes | D7: Yes | E7: =VLOOKUP(C7,CategoryMap,2,0) | F7: =VLOOKUP(D7,CategoryMap,2,0) | G7: =ABS(E7-F7) | H7: =IF(G7=0,"Yes","No") | I7: Yes | J7: =IF(I7="","",IF(AND(I7=C7,I7=D7),"Both",IF(I7=C7,"Opus",IF(I7=D7,"Sonnet","Neither"))))
A8: R003 | B8: Q7 | C8: Yes | D8: Yes | E8: =VLOOKUP(C8,CategoryMap,2,0) | F8: =VLOOKUP(D8,CategoryMap,2,0) | G8: =ABS(E8-F8) | H8: =IF(G8=0,"Yes","No") | I8: Yes | J8: =IF(I8="","",IF(AND(I8=C8,I8=D8),"Both",IF(I8=C8,"Opus",IF(I8=D8,"Sonnet","Neither"))))
A9: R003 | B9: Q8 | C9: Partial | D9: No | E9: =VLOOKUP(C9,CategoryMap,2,0) | F9: =VLOOKUP(D9,CategoryMap,2,0) | G9: =ABS(E9-F9) | H9: =IF(G9=0,"Yes","No") | I9: No | J9: =IF(I9="","",IF(AND(I9=C9,I9=D9),"Both",IF(I9=C9,"Opus",IF(I9=D9,"Sonnet","Neither"))))
A10: R006 | B10: Q1 | C10: Yes | D10: Yes | E10: =VLOOKUP(C10,CategoryMap,2,0) | F10: =VLOOKUP(D10,CategoryMap,2,0) | G10: =ABS(E10-F10) | H10: =IF(G10=0,"Yes","No") | I10: Yes | J10: =IF(I10="","",IF(AND(I10=C10,I10=D10),"Both",IF(I10=C10,"Opus",IF(I10=D10,"Sonnet","Neither"))))
A11: R006 | B11: Q2 | C11: Yes | D11: Yes | E11: =VLOOKUP(C11,CategoryMap,2,0) | F11: =VLOOKUP(D11,CategoryMap,2,0) | G11: =ABS(E11-F11) | H11: =IF(G11=0,"Yes","No") | I11: Yes | J11: =IF(I11="","",IF(AND(I11=C11,I11=D11),"Both",IF(I11=C11,"Opus",IF(I11=D11,"Sonnet","Neither"))))
A12: R006 | B12: Q3 | C12: Yes | D12: Yes | E12: =VLOOKUP(C12,CategoryMap,2,0) | F12: =VLOOKUP(D12,CategoryMap,2,0) | G12: =ABS(E12-F12) | H12: =IF(G12=0,"Yes","No") | I12: Yes | J12: =IF(I12="","",IF(AND(I12=C12,I12=D12),"Both",IF(I12=C12,"Opus",IF(I12=D12,"Sonnet","Neither"))))
A13: R006 | B13: Q4 | C13: Partial | D13: Yes | E13: =VLOOKUP(C13,CategoryMap,2,0) | F13: =VLOOKUP(D13,CategoryMap,2,0) | G13: =ABS(E13-F13) | H13: =IF(G13=0,"Yes","No") | I13: Yes | J13: =IF(I13="","",IF(AND(I13=C13,I13=D13),"Both",IF(I13=C13,"Opus",IF(I13=D13,"Sonnet","Neither"))))
... A1497: R405 | B1497: Q8 | C1497: Partial | D1497: No | E1497: =VLOOKUP(C1497,CategoryMap,2,0) | F1497: =VLOOKUP(D1497,CategoryMap,2,0) | G1497: =ABS(E1497-F1497) | H1497: =IF(G1497=0,"Yes","No") | I1497: Partial | J1497: =IF(I1497="","",IF(AND(I1497=C1497,I1497=D1497),"Both",IF(I1497=C1497,"Opus",IF(I1497=D1497,"Sonnet","Neither"))))

Sheet CategoryMap
A1: Category | B1: Code
A2: No | B2: 0
A3: Partial | B3: 1
A4: Yes | B4: 2

Sheet Weights
A1: Weight matrix (linear-weighted kappa) — distance between categories / 2
A3: Opus \ Sonnet | B3: No | C3: Partial | D3: Yes
A4: No | B4: =ABS(0-0)/2 | C4: =ABS(0-1)/2 | D4: =ABS(0-2)/2
A5: Partial | B5: =ABS(1-0)/2 | C5: =ABS(1-1)/2 | D5: =ABS(1-2)/2
A6: Yes | B6: =ABS(2-0)/2 | C6: =ABS(2-1)/2 | D6: =ABS(2-2)/2
A8: Weight 0 = exact agreement; 0.5 = 1-step disagreement (e.g., Partial vs. Yes); 1 = 2-step disagreement (No vs. Yes).

Sheet Confusion_matrix
A1: Opus × Sonnet confusion matrices, by question (rows=Opus, columns=Sonnet)
A3: Q1
A4: Opus \ Sonnet | B4: No | C4: Partial | D4: Yes | E4: Total (Opus)
A5: No | B5: =COUNTIFS(Data!$B$2:$B$1497,"Q1",Data!$E$2:$E$1497,0,Data!$F$2:$F$1497,0) | C5: =COUNTIFS(Data!$B$2:$B$1497,"Q1",Data!$E$2:$E$1497,0,Data!$F$2:$F$1497,1) | D5: =COUNTIFS(Data!$B$2:$B$1497,"Q1",Data!$E$2:$E$1497,0,Data!$F$2:$F$1497,2) | E5: =SUM(B5:D5)
A6: Partial | B6: =COUNTIFS(Data!$B$2:$B$1497,"Q1",Data!$E$2:$E$1497,1,Data!$F$2:$F$1497,0) | C6: =COUNTIFS(Data!$B$2:$B$1497,"Q1",Data!$E$2:$E$1497,1,Data!$F$2:$F$1497,1) | D6: =COUNTIFS(Data!$B$2:$B$1497,"Q1",Data!$E$2:$E$1497,1,Data!$F$2:$F$1497,2) | E6: =SUM(B6:D6)
A7: Yes | B7: =COUNTIFS(Data!$B$2:$B$1497,"Q1",Data!$E$2:$E$1497,2,Data!$F$2:$F$1497,0) | C7: =COUNTIFS(Data!$B$2:$B$1497,"Q1",Data!$E$2:$E$1497,2,Data!$F$2:$F$1497,1) | D7: =COUNTIFS(Data!$B$2:$B$1497,"Q1",Data!$E$2:$E$1497,2,Data!$F$2:$F$1497,2) | E7: =SUM(B7:D7)
A8: Total (Sonnet) | B8: =SUM(B5:B7) | C8: =SUM(C5:C7) | D8: =SUM(D5:D7) | E8: =SUM(B8:D8)
A10: Q2
A11: Opus \ Sonnet | B11: No | C11: Partial | D11: Yes | E11: Total (Opus)
A12: No | B12: =COUNTIFS(Data!$B$2:$B$1497,"Q2",Data!$E$2:$E$1497,0,Data!$F$2:$F$1497,0) | C12: =COUNTIFS(Data!$B$2:$B$1497,"Q2",Data!$E$2:$E$1497,0,Data!$F$2:$F$1497,1) | D12: =COUNTIFS(Data!$B$2:$B$1497,"Q2",Data!$E$2:$E$1497,0,Data!$F$2:$F$1497,2) | E12: =SUM(B12:D12)
A13: Partial | B13: =COUNTIFS(Data!$B$2:$B$1497,"Q2",Data!$E$2:$E$1497,1,Data!$F$2:$F$1497,0) | C13: =COUNTIFS(Data!$B$2:$B$1497,"Q2",Data!$E$2:$E$1497,1,Data!$F$2:$F$1497,1) | D13: =COUNTIFS(Data!$B$2:$B$1497,"Q2",Data!$E$2:$E$1497,1,Data!$F$2:$F$1497,2) | E13: =SUM(B13:D13)
A14: Yes | B14: =COUNTIFS(Data!$B$2:$B$1497,"Q2",Data!$E$2:$E$1497,2,Data!$F$2:$F$1497,0) | C14: =COUNTIFS(Data!$B$2:$B$1497,"Q2",Data!$E$2:$E$1497,2,Data!$F$2:$F$1497,1) | D14: =COUNTIFS(Data!$B$2:$B$1497,"Q2",Data!$E$2:$E$1497,2,Data!$F$2:$F$1497,2) | E14: =SUM(B14:D14)
A15: Total (Sonnet) | B15: =SUM(B12:B14) | C15: =SUM(C12:C14) | D15: =SUM(D12:D14) | E15: =SUM(B15:D15)
A17: Q3
A18: Opus \ Sonnet | B18: No | C18: Partial | D18: Yes | E18: Total (Opus)
A19: No | B19: =COUNTIFS(Data!$B$2:$B$1497,"Q3",Data!$E$2:$E$1497,0,Data!$F$2:$F$1497,0) | C19: =COUNTIFS(Data!$B$2:$B$1497,"Q3",Data!$E$2:$E$1497,0,Data!$F$2:$F$1497,1) | D19: =COUNTIFS(Data!$B$2:$B$1497,"Q3",Data!$E$2:$E$1497,0,Data!$F$2:$F$1497,2) | E19: =SUM(B19:D19)
A20: Partial | B20: =COUNTIFS(Data!$B$2:$B$1497,"Q3",Data!$E$2:$E$1497,1,Data!$F$2:$F$1497,0) | C20: =COUNTIFS(Data!$B$2:$B$1497,"Q3",Data!$E$2:$E$1497,1,Data!$F$2:$F$1497,1) | D20: =COUNTIFS(Data!$B$2:$B$1497,"Q3",Data!$E$2:$E$1497,1,Data!$F$2:$F$1497,2) | E20: =SUM(B20:D20)
A21: Yes | B21: =COUNTIFS(Data!$B$2:$B$1497,"Q3",Data!$E$2:$E$1497,2,Data!$F$2:$F$1497,0) | C21: =COUNTIFS(Data!$B$2:$B$1497,"Q3",Data!$E$2:$E$1497,2,Data!$F$2:$F$1497,1) | D21: =COUNTIFS(Data!$B$2:$B$1497,"Q3",Data!$E$2:$E$1497,2,Data!$F$2:$F$1497,2) | E21: =SUM(B21:D21)
A22: Total (Sonnet) | B22: =SUM(B19:B21) | C22: =SUM(C19:C21) | D22: =SUM(D19:D21) | E22: =SUM(B22:D22)
A24: Q4
A25: Opus \ Sonnet | B25: No | C25: Partial | D25: Yes | E25: Total (Opus)
A26: No | B26: =COUNTIFS(Data!$B$2:$B$1497,"Q4",Data!$E$2:$E$1497,0,Data!$F$2:$F$1497,0) | C26: =COUNTIFS(Data!$B$2:$B$1497,"Q4",Data!$E$2:$E$1497,0,Data!$F$2:$F$1497,1) | D26: =COUNTIFS(Data!$B$2:$B$1497,"Q4",Data!$E$2:$E$1497,0,Data!$F$2:$F$1497,2) | E26: =SUM(B26:D26)
A27: Partial | B27: =COUNTIFS(Data!$B$2:$B$1497,"Q4",Data!$E$2:$E$1497,1,Data!$F$2:$F$1497,0) | C27: =COUNTIFS(Data!$B$2:$B$1497,"Q4",Data!$E$2:$E$1497,1,Data!$F$2:$F$1497,1) | D27: =COUNTIFS(Data!$B$2:$B$1497,"Q4",Data!$E$2:$E$1497,1,Data!$F$2:$F$1497,2) | E27: =SUM(B27:D27)
A28: Yes | B28: =COUNTIFS(Data!$B$2:$B$1497,"Q4",Data!$E$2:$E$1497,2,Data!$F$2:$F$1497,0) | C28: =COUNTIFS(Data!$B$2:$B$1497,"Q4",Data!$E$2:$E$1497,2,Data!$F$2:$F$1497,1) | D28: =COUNTIFS(Data!$B$2:$B$1497,"Q4",Data!$E$2:$E$1497,2,Data!$F$2:$F$1497,2) | E28: =SUM(B28:D28)
A29: Total (Sonnet) | B29: =SUM(B26:B28) | C29: =SUM(C26:C28) | D29: =SUM(D26:D28) | E29: =SUM(B29:D29)
A31: Q5
A32: Opus \ Sonnet | B32: No | C32: Partial | D32: Yes | E32: Total (Opus)
A33: No | B33: =COUNTIFS(Data!$B$2:$B$1497,"Q5",Data!$E$2:$E$1497,0,Data!$F$2:$F$1497,0) | C33: =COUNTIFS(Data!$B$2:$B$1497,"Q5",Data!$E$2:$E$1497,0,Data!$F$2:$F$1497,1) | D33: =COUNTIFS(Data!$B$2:$B$1497,"Q5",Data!$E$2:$E$1497,0,Data!$F$2:$F$1497,2) | E33: =SUM(B33:D33)
A34: Partial | B34: =COUNTIFS(Data!$B$2:$B$1497,"Q5",Data!$E$2:$E$1497,1,Data!$F$2:$F$1497,0) | C34: =COUNTIFS(Data!$B$2:$B$1497,"Q5",Data!$E$2:$E$1497,1,Data!$F$2:$F$1497,1) | D34: =COUNTIFS(Data!$B$2:$B$1497,"Q5",Data!$E$2:$E$1497,1,Data!$F$2:$F$1497,2) | E34: =SUM(B34:D34)
A35: Yes | B35: =COUNTIFS(Data!$B$2:$B$1497,"Q5",Data!$E$2:$E$1497,2,Data!$F$2:$F$1497,0) | C35: =COUNTIFS(Data!$B$2:$B$1497,"Q5",Data!$E$2:$E$1497,2,Data!$F$2:$F$1497,1) | D35: =COUNTIFS(Data!$B$2:$B$1497,"Q5",Data!$E$2:$E$1497,2,Data!$F$2:$F$1497,2) | E35: =SUM(B35:D35)
A36: Total (Sonnet) | B36: =SUM(B33:B35) | C36: =SUM(C33:C35) | D36: =SUM(D33:D35) | E36: =SUM(B36:D36)
A38: Q6
A39: Opus \ Sonnet | B39: No | C39: Partial | D39: Yes | E39: Total (Opus)
A40: No | B40: =COUNTIFS(Data!$B$2:$B$1497,"Q6",Data!$E$2:$E$1497,0,Data!$F$2:$F$1497,0) | C40: =COUNTIFS(Data!$B$2:$B$1497,"Q6",Data!$E$2:$E$1497,0,Data!$F$2:$F$1497,1) | D40: =COUNTIFS(Data!$B$2:$B$1497,"Q6",Data!$E$2:$E$1497,0,Data!$F$2:$F$1497,2) | E40: =SUM(B40:D40)
A41: Partial | B41: =COUNTIFS(Data!$B$2:$B$1497,"Q6",Data!$E$2:$E$1497,1,Data!$F$2:$F$1497,0) | C41: =COUNTIFS(Data!$B$2:$B$1497,"Q6",Data!$E$2:$E$1497,1,Data!$F$2:$F$1497,1) | D41: =COUNTIFS(Data!$B$2:$B$1497,"Q6",Data!$E$2:$E$1497,1,Data!$F$2:$F$1497,2) | E41: =SUM(B41:D41)
A42: Yes | B42: =COUNTIFS(Data!$B$2:$B$1497,"Q6",Data!$E$2:$E$1497,2,Data!$F$2:$F$1497,0) | C42: =COUNTIFS(Data!$B$2:$B$1497,"Q6",Data!$E$2:$E$1497,2,Data!$F$2:$F$1497,1) | D42: =COUNTIFS(Data!$B$2:$B$1497,"Q6",Data!$E$2:$E$1497,2,Data!$F$2:$F$1497,2) | E42: =SUM(B42:D42)
A43: Total (Sonnet) | B43: =SUM(B40:B42) | C43: =SUM(C40:C42) | D43: =SUM(D40:D42) | E43: =SUM(B43:D43)
A45: Q7
A46: Opus \ Sonnet | B46: No | C46: Partial | D46: Yes | E46: Total (Opus)
A47: No | B47: =COUNTIFS(Data!$B$2:$B$1497,"Q7",Data!$E$2:$E$1497,0,Data!$F$2:$F$1497,0) | C47: =COUNTIFS(Data!$B$2:$B$1497,"Q7",Data!$E$2:$E$1497,0,Data!$F$2:$F$1497,1) | D47: =COUNTIFS(Data!$B$2:$B$1497,"Q7",Data!$E$2:$E$1497,0,Data!$F$2:$F$1497,2) | E47: =SUM(B47:D47)
...

Sheet Kappa_by_question
A1: Question | B1: N | C1: Do (observed disagreement) | D1: De (disagreement expected by chance) | E1: Weighted kappa | F1: Interpretation (Landis & Koch, 1977)
A2: Q1 | B2: =Confusion_matrix!E8 | C2: =SUMPRODUCT(Weights!$B$4:$D$6,Confusion_matrix!B5:D7)/B2 | D2: =SUMPRODUCT(Weights!$B$4:$D$6,MMULT(Confusion_matrix!E5:E7,Confusion_matrix!B8:D8))/(B2^2) | E2: =1-C2/D2 | F2: =IF(E2<0,"Poor",IF(E2<=0.2,"Slight",IF(E2<=0.4,"Fair",IF(E2<=0.6,"Moderate",IF(E2<=0.8,"Substantial","Almost perfect")))))
A3: Q2 | B3: =Confusion_matrix!E15 | C3: =SUMPRODUCT(Weights!$B$4:$D$6,Confusion_matrix!B12:D14)/B3 | D3: =SUMPRODUCT(Weights!$B$4:$D$6,MMULT(Confusion_matrix!E12:E14,Confusion_matrix!B15:D15))/(B3^2) | E3: =1-C3/D3 | F3: =IF(E3<0,"Poor",IF(E3<=0.2,"Slight",IF(E3<=0.4,"Fair",IF(E3<=0.6,"Moderate",IF(E3<=0.8,"Substantial","Almost perfect")))))
A4: Q3 | B4: =Confusion_matrix!E22 | C4: =SUMPRODUCT(Weights!$B$4:$D$6,Confusion_matrix!B19:D21)/B4 | D4: =SUMPRODUCT(Weights!$B$4:$D$6,MMULT(Confusion_matrix!E19:E21,Confusion_matrix!B22:D22))/(B4^2) | E4: =1-C4/D4 | F4: =IF(E4<0,"Poor",IF(E4<=0.2,"Slight",IF(E4<=0.4,"Fair",IF(E4<=0.6,"Moderate",IF(E4<=0.8,"Substantial","Almost perfect")))))
A5: Q4 | B5: =Confusion_matrix!E29 | C5: =SUMPRODUCT(Weights!$B$4:$D$6,Confusion_matrix!B26:D28)/B5 | D5: =SUMPRODUCT(Weights!$B$4:$D$6,MMULT(Confusion_matrix!E26:E28,Confusion_matrix!B29:D29))/(B5^2) | E5: =1-C5/D5 | F5: =IF(E5<0,"Poor",IF(E5<=0.2,"Slight",IF(E5<=0.4,"Fair",IF(E5<=0.6,"Moderate",IF(E5<=0.8,"Substantial","Almost perfect")))))
A6: Q5 | B6: =Confusion_matrix!E36 | C6: =SUMPRODUCT(Weights!$B$4:$D$6,Confusion_matrix!B33:D35)/B6 | D6: =SUMPRODUCT(Weights!$B$4:$D$6,MMULT(Confusion_matrix!E33:E35,Confusion_matrix!B36:D36))/(B6^2) | E6: =1-C6/D6 | F6: =IF(E6<0,"Poor",IF(E6<=0.2,"Slight",IF(E6<=0.4,"Fair",IF(E6<=0.6,"Moderate",IF(E6<=0.8,"Substantial","Almost perfect")))))
A7: Q6 | B7: =Confusion_matrix!E43 | C7: =SUMPRODUCT(Weights!$B$4:$D$6,Confusion_matrix!B40:D42)/B7 | D7: =SUMPRODUCT(Weights!$B$4:$D$6,MMULT(Confusion_matrix!E40:E42,Confusion_matrix!B43:D43))/(B7^2) | E7: =1-C7/D7 | F7: =IF(E7<0,"Poor",IF(E7<=0.2,"Slight",IF(E7<=0.4,"Fair",IF(E7<=0.6,"Moderate",IF(E7<=0.8,"Substantial","Almost perfect")))))
A8: Q7 | B8: =Confusion_matrix!E50 | C8: =SUMPRODUCT(Weights!$B$4:$D$6,Confusion_matrix!B47:D49)/B8 | D8: =SUMPRODUCT(Weights!$B$4:$D$6,MMULT(Confusion_matrix!E47:E49,Confusion_matrix!B50:D50))/(B8^2) | E8: =1-C8/D8 | F8: =IF(E8<0,"Poor",IF(E8<=0.2,"Slight",IF(E8<=0.4,"Fair",IF(E8<=0.6,"Moderate",IF(E8<=0.8,"Substantial","Almost perfect")))))
A9: Q8 | B9: =Confusion_matrix!E57 | C9: =SUMPRODUCT(Weights!$B$4:$D$6,Confusion_matrix!B54:D56)/B9 | D9: =SUMPRODUCT(Weights!$B$4:$D$6,MMULT(Confusion_matrix!E54:E56,Confusion_matrix!B57:D57))/(B9^2) | E9: =1-C9/D9 | F9: =IF(E9<0,"Poor",IF(E9<=0.2,"Slight",IF(E9<=0.4,"Fair",IF(E9<=0.6,"Moderate",IF(E9<=0.8,"Substantial","Almost perfect")))))
A10: Overall (Q1-Q8) | B10: =Confusion_matrix!E64 | C10: =SUMPRODUCT(Weights!$B$4:$D$6,Confusion_matrix!B61:D63)/B10 | D10: =SUMPRODUCT(Weights!$B$4:$D$6,MMULT(Confusion_matrix!E61:E63,Confusion_matrix!B64:D64))/(B10^2) | E10: =1-C10/D10 | F10: =IF(E10<0,"Poor",IF(E10<=0.2,"Slight",IF(E10<=0.4,"Fair",IF(E10<=0.6,"Moderate",IF(E10<=0.8,"Substantial","Almost perfect")))))
A12: Threshold for gate G3 (Method, 2.7): overall weighted kappa ≥ 0.60.

Sheet Kappa_by_study
A1: Kappa by study (8 Q1-Q8 pairs each) — computed by the generating script with the same linear-weighted kappa formula; it is not a worksheet formula here because, with only 8 pairs per row, the per-study confusion matrix would have a zero denominator whenever the study has no disagreement at all — simpler to handle in code than in a formula.
A3: Study_ID | B3: Weighted kappa (8 questions)
A4: R003 | B4: 0.3333
A5: R006 | B5: 0.3846
A6: R011 | B6: 0.6
A7: R012 | B7: 0.7895
A8: R013 | B8: 0.7143
A9: R017 | B9: 1
A10: R018 | B10: 1
A11: R020 | B11: 0.4
A12: R021 | B12: 1
A13: R022 | B13: 0.7143
A14: R023 | B14: 0.4286
A15: R033 | B15: 0.25
... A190: R405 | B190: -0.0667
A192: Median | B192: =MEDIAN(B4:B190)
A193: Mean | B193: =AVERAGE(B4:B190)
